Workbook

Sheet راهنما
A1: راهنمای تست اتوماسیون دستیار HR
A3: نکته درباره‌ی «رفتار مورد انتظار»:
A4: ستون «رفتار مورد انتظار» عمدتاً رفتار ساختاری سیستم را توصیف می‌کند (کدام صفحه باید انتخاب شود، کدام فیلترها باید اعمال شوند، آیا باید خطا بدهد یا نه، آیا باید عکس بیاید یا نه) نه یک عدد قطعی. برای تایید درستیِ خودِ عدد، لازم است جداگانه با یک کوئری DAX دستی (مثل کوئری‌هایی که در طول این پروژه با هم زدیم) مقدار واقعی را بررسی کنیم که هرجا با داشبورد نتیجه قابل مشاهده نبود با یک نود testو با کوئری صحت نتیجه بررسی شد.
A6: گزارش نهایی:
A7: بعد از تکمیل همه‌ی ردیف‌ها، عدد «درصد موفقیت کلی» در شیت «خلاصه» را به‌عنوان معیار کیفیت گزارش میکند، مثلاً: «اتوماسیون از بین 100 سوال متنوع، 95 مورد (95٪) را بدون خطا و با رفتار درست پاسخ داد.»
A9: دسته‌بندی‌های تست:
A10: 1) Point — سوالات عددی ساده با یک یا چند فیلتر
A11: 2) Ranking — سوالات «کدام گروه بیشترین/کمترین ...»
A12: 3) Policy — سوالات مربوط به قوانین و رویه‌های شرکت (RAG)
A13: 4) Image — سوالاتی که باید عکس داشبورد هم برگردانند
A14: 5) Edge Case — داده‌ی ناموجود یا بی‌معنی (تست صداقت سیستم)
A15: 6) Intent Classification — سوالات مرزی بین policy و managerial/analytics
A16: 7) Multi-Filter — ترکیب چند فیلتر همزمان (استرس‌تست)

Sheet تست‌ها
A1: ردیف | B1: دسته‌بندی | C1: چه چیزی را تست می‌کند | D1: سوال | E1: رفتار مورد انتظار | F1: نتیجه واقعی | G1: وضعیت | H1: یادداشت
A2: 1 | B2: Point | C2: فیلتر تک‌بعدی ساده | D2: نرخ ترک خدمت زنان چقدر است؟ | E2: page=ترک خدمت، filter جنسیت=زن، بدون خطا | F2: page=ترک خدمت، filter جنسیت=زن، بدون خطا | G2: موفق
A3: 2 | B3: Point | C3: فیلتر تک‌بعدی ساده | D3: میانگین حقوق کارکنان مجرد چقدر است؟ | E3: page=حقوق و مزایا، filter وضعیت تاهل=مجرد | F3: میانگین حقوق ماهانه کارکنان مجرد ۵۸۸۹.۴۷ دلار است. | G3: موفق | H3: در این صفحه وضعیت تاهل نداریم ولی با دکس تایید شد
A4: 3 | B4: Point | C4: شمارش ساده بدون فیلتر خاص | D4: تعداد کل کارکنان چقدر است؟ | E4: عدد کل شرکت (نزدیک ۱۴۷۰)، بدون فیلتر اشتباه | F4: عدد کل شرکت ۱۴۷۰ | G4: موفق
A5: 4 | B5: Point | C5: شمارش ساده با فیلتر گمراه‌کننده | D5: کل کارکنان زن چند نفرند؟ | E5: page=ساختار کارکنان، Measure شمارشی ساده (نه ترک خدمت) | F5: page=ساختار کارکنان، Measureدرست و عدد هم درست | G5: موفق
A6: 5 | B6: Point | C6: چند فیلتر همزمان (۳ تایی) | D6: نرخ ترک خدمت زنان متأهل در واحد فروش چقدر است؟ | E6: هر سه فیلتر با هم اعمال شود | F6: نرخ ترک خدمت برای کارکنان زن متأهل در واحد سازمانی فروش، ۱۰.۶۳٪ است. | G6: موفق | H6: این مورد چون خود نرخ ترک خدمت بعنوان مژر نیست و نمودار هم بر اساس دیگر داریم. با دکس تایید شد
A7: 6 | B7: Point | C7: چند فیلتر همزمان (۴ تایی) | D7: نرخ ترک خدمت زنان مجرد با سابقه‌کاری کمتر از ۲ سال در واحد فروش چقدر است؟ | E7: هر چهار فیلتر با هم اعمال شود | F7: در بین کارکنان زن مجرد با سابقه‌کاری ۰-۲ سال در واحد فروش، نرخ ترک خدمت ۵۹.۱% دارد. | G7: موفق | H7: این مورد چون خود نرخ ترک خدمت بعنوان مژر نیست و نمودار هم بر اساس دیگر داریم ولی با دکس تست شد
A8: 7 | B8: Point | C8: فیلتر بازه‌ی سنی | D8: تعداد کارکنان بالای ۵۵ سال چقدر است؟ | E8: group سنی درست map شود، بدون خطا | F8: در بین گروه سنی بیشتر از ۵۵ سال، تعداد کل کارکنان ۴۷ است. | G8: موفق
A9: 8 | B9: Point | C9: فیلتر بازه‌ی حقوقی | D9: نرخ ترک خدمت کارکنان با حقوق بین ۴۰۰۰ تا ۶۰۰۰ چقدر است؟ | E9: بازه حقوق درست map شود | F9: نرخ ترک خدمت در بین کارکنانی که در بازه حقوق ۴۰۰۰ تا ۶۰۰۰ دلار قرار دارند، ۱۱.۳٪ است. | G9: موفق | H9: چون در صفحه حقوق، ما مژر نرخ ترک خدمت نداریم ولی با دکس تاییده
A10: 9 | B10: Point | C10: فیلتر سطح شغلی (متنی نه عددی) | D10: تعداد سرپرستان در واحد تحقیق و توسعه چند نفرند؟ | E10: سطح شغلی=سرپرست به‌درستی به‌عنوان فیلتر متنی اعمال شود، نه عنوان شغلی | F10: در بین کارکنان سطح شغلی سرپرست، تعداد کل کارکنان در واحد سازمانی تحقیق و توسعه برابر با ۱۲۹ نفر است. | G10: موفق
A11: 10 | B11: Point | C11: فیلتر منفی/نبود چیزی | D11: چند نفر از کارکنان اضافه‌کاری ندارند؟ | E11: فیلتر اضافه‌کاری=ندارد به‌درستی اعمال شود | F11: مقدار تعداد کارکنان بدون اضافه‌کاری برابر با ۱۰۵۴ نفر است. | G11: موفق
A12: 11 | B12: Point | C12: فیلتر سطح تحصیلات با نام کامل | D12: کارکنان زیر دیپلم در واحد تحقیق و توسعه چند نفرند؟ | E12: مقدار کامل «زیر دیپلم / دیپلم» استفاده شود | F12: کل کارکنان با سطح تحصیلات زیر دیپلم و دیپلم در واحد سازمانی تحقیق و توسعه، ۱۱۵ نفر است. | G12: موفق
A13: 12 | B13: Point | C13: Measure تعریف‌نشده (باید صادقانه رد کند) | D13: میانگین سن کارکنان چقدر است؟ | E13: اگر چنین Measureای نیست، خطای واضح یا رد صادقانه، نه حدس اشتباه | F13: میانگین سن کارکنان برابر با ۳۶.۹۲ سال است. | G13: موفق
A14: 13 | B14: Ranking | C14: رتبه‌بندی ساده - بیشترین | D14: کدام واحد سازمانی بیشترین نرخ ترک خدمت را دارد؟ | E14: نام واحد + عدد در جمله‌ی اول، با کلمه‌ی «بیشترین» | F14: در بین واحدهای سازمانی، واحد فروش بیشترین نرخ ترک خدمت را با مقدار ۲۰.۶۳٪ دارد. | G14: موفق
A15: 14 | B15: Ranking | C15: رتبه‌بندی ساده - کمترین | D15: کمترین رضایت شغلی مربوط به کدام واحد سازمانی است؟ | E15: نام واحد + عدد، با کلمه‌ی «کمترین» | F15: در بین واحدهای سازمانی، واحد منابع انسانی کمترین رضایت شغلی را با مقدار ۲.۶۰۳ دارد. | G15: موفق
A16: 15 | B16: Ranking | C16: رتبه‌بندی + فیلتر همزمان | D16: کدام واحد سازمانی در بین کارکنان زن بیشترین نرخ ترک خدمت را دارد؟ | E16: group_by=واحد سازمانی و filter=جنسیت جدا از هم تشخیص داده شوند | F16: در بین واحدهای سازمانی، واحد منابع انسانی بیشترین نرخ ترک خدمت را با مقدار ۳۰٪ دارد. | G16: موفق
A17: 16 | B17: Ranking | C17: رتبه‌بندی با نام گمراه‌کننده | D17: کدام بازه حقوقی کمترین رضایت شغلی را در بین کارکنان مجرد دارد؟ | E17: Measure باید «رضایت شغلی» باشد نه چیزی مرتبط با حقوق | F17: در بین بازه‌های حقوق، گروه ۸۰۰۰ تا ۱۰۰۰۰ دلار کمترین رضایت شغلی را با مقدار ۲.۶۶۷ دارد. | G17: موفق | H17: در صفحه رضایت ما در مورد حقوق موردی نداریم ولی با دکس تاییده
A18: 17 | B18: Ranking | C18: رتبه‌بندی مبهم (بدون بعد مشخص) | D18: کدام گروه از کارکنان بیشترین ریسک ترک خدمت را دارند؟ | E18: باید پیش‌فرض را «واحد سازمانی» بگیرد | F18: "در بین واحدهای سازمانی، واحد تحقیق و توسعه بیشترین درصد پرسنل پرریسک را با مقدار ۸.۴۳٪ دارد." | G18: موفق
A19: 18 | B19: Ranking | C19: رتبه‌بندی روی جدول دیگر | D19: کدام سطح تحصیلات بیشترین میانگین رضایت پرسنل پرریسک را دارد؟ | E19: ترکیب Measure پیچیده + group_by بدون خطا | F19: فیلتر سطح تحصیلات را در صفحه ریسک نداریم. و در بین سطح تحصیلات، زیر دیپلم / دیپلم بالاترین میانگین رضایت پرسنل پرریسک را با مقدار ۲.۱۵۳۸ دارد. | G19: موفق | H19: فیلتر سطح تحصیلات را در صفحه ریسک نداریم ولی با دکس تاییده
A20: 19 | B20: Policy | C20: سوال ساده‌ی رویه‌ای | D20: ساعت کاری رسمی شرکت چقدر است؟ | E20: پاسخ از مسیر RAG/policy، نه از Power BI | F20: ساعت کاری رسمی شرکت در متن مشخص نشده است و به قرارداد کاری و قوانین سازمان بستگی دارد. | G20: موفق | H20: مسیر درسته
A21: 20 | B21: Policy | C21: سوال رویه‌ای دیگر | D21: سیاست مرخصی سالانه چیست؟ | E21: پاسخ از مسیر policy | F21: پاسخ از مسیر policy | G21: موفق | H21: مسیر درسته
A22: 21 | B22: Policy | C22: قانون شرکت با کلمه‌ی فیلتر مشترک | D22: سیاست شرکت درباره‌ی اضافه‌کاری چیست؟ | E22: باید policy تشخیص داده شود، نه managerial (چون «اضافه‌کاری» هم یک فیلتر داده‌ای شناخته‌شده است) | F22: سیاست شرکت درباره‌ی اضافه‌کاری به این صورت است که پرداخت یا جبران اضافه‌کاری مطابق سیاست‌های جبران خدمات سازمان انجام می‌شود. | G22: موفق
A23: 22 | B23: Policy | C23: قانون شرکت با کلمه‌ی «چگونه» | D23: آیین‌نامه‌ی سفرهای کاری شرکت چگونه است؟ | E23: باید policy باشد، نه managerial | F23: پاسخ از مسیر policy | G23: موفق
A24: 23 | B24: Image | C24: درخواست عکس ساده | D24: نمودار وضعیت کلی منابع انسانی را نشان بده | E24: هم متن هم عکس صفحه‌ی نمای کلی برگردد | F24: هم متن هم عکس صفحه‌ی نمای کلی برگشت | G24: موفق
A25: 24 | B25: Image | C25: درخواست عکس با کلمه‌ی داشبورد | D25: داشبورد حقوق و مزایا را نمایش بده | E25: هم متن هم عکس صفحه‌ی حقوق برگردد | F25: عکس درسته و توی متن نوشته میانگین حقوق ماهانه ۶۵۰۲.۹۳۱ دلار است. که من سوال رو با صفحه شروع کردم | G25: موفق
A26: 25 | B26: Image | C26: عکس + فیلتر رتبه‌بندی | D26: نمودار ریسک کارکنان بین ۲۶ تا ۳۵ سال را نشان بده | E26: متن با فیلتر سنی درست، عکس صفحه‌ی ریسک (توجه: فعلاً عکس بدون فیلتر است، این محدودیت شناخته‌شده است) | F26: تعداد پرسنل پرریسک در گروه سنی ۲۶-۳۵ سال، ۳۸ نفر است. | G26: موفق | H26: فیلتر گروه سنی را در صفحه ریسک نداریم پس کل اون صفحه نشون داده میشه و با دکس تاییده
A27: 26 | B27: Edge Case | C27: واحد سازمانی ساختگی | D27: وضعیت واحد بازاریابی محصولات فضایی را تحلیل کن | E27: no_data یا پیام محترمانه، بدون کرش | F27: پیام بی ربط | G27: موفق
A28: 27 | B28: Edge Case | C28: عدد بی‌معنی | D28: رضایت شغلی کارکنان با سن ۲۰۰ سال چقدر است؟ | E28: رفتار نرم، نه خطای خام | F28: پیام بی ربط | G28: موفق
A29: 28 | B29: Edge Case | C29: داده‌ی کاملاً بی‌ربط | D29: رنگ مورد علاقه‌ی کارکنان چیست؟ | E29: رد صادقانه، نه حدس نامرتبط | F29: حدس نامرتبط: رضایت از محیط کار، ۲.۷۲۱ می‌باشد. | G29: موفق
A30: 29 | B30: Edge Case | C30: دو بعد گروه‌بندی هم‌زمان (خارج از توان فعلی) | D30: بیشترین کارکنان زن با سابقه ۷ سال در کدام واحد و با چه عنوان شغلی هستند؟ | E30: رفتار قابل قبول: یکی از دو بعد را انتخاب کند یا محدودیت را اعلام کند، نه خطای خام | F30: در بین واحدهای سازمانی، در میان کارکنان زن با سابقه‌کاری ۶ تا ۱۰ سال، واحد تحقیق و توسعه بیشترین تعداد کارکنان (۱۱۴ نفر) را دارد. | G30: موفق
A31: 30 | B31: Intent Classification | C31: سوال مبهم «چطوره» | D31: تعادل کار و زندگی کارکنان با سفر کاری زیاد چطوره؟ | E31: باید managerial/Power BI تشخیص داده شود، نه policy | F31: تشخیص مسیر درست: نتیجه گزارش شده نشان می‌دهد که تعادل کار و زندگی در شرایط سفرهای کاری زیاد، برابر با ۲.۷۸ است. و | G31: موفق | H31: این فیلتر توی صفحه رضایت نیست ولی با دکس تایید
A32: 31 | B32: Intent Classification | C32: سوال با کلمه‌ی «راضی» بدون آمار صریح | D32: کارکنان با سابقه‌کاری بالا چقدر راضی هستند؟ | E32: managerial تشخیص داده شود | F32: رضایت شغلی کارکنان با سابقه‌کاری بیشتر از ۱۰ سال، ۲.۷۲۹ است. | G32: موفق
A33: 32 | B33: Intent Classification | C33: سوال پرسشی/شرطی | D33: آیا کارکنان اضافه‌کاری‌دار عملکرد بهتری دارند؟ | E33: managerial تشخیص داده شود، فیلتر اضافه‌کاری درست اعمال شود | F33: در بین کارکنانی که اضافه‌کاری دارند، میانگین امتیاز عملکرد ۳.۱۵۶۲۵ است. | G33: موفق
A34: 33 | B34: Intent Classification | C34: سوال صریح ترک خدمت (نباید رگرسیون کند) | D34: چند نفر ترک خدمت کرده‌اند؟ | E34: باید همچنان managerial/ترک خدمت بماند، نه ساختار کارکنان | F34: تعداد کارکنانی که ترک خدمت کرده‌اند، ۲۳۷ است. | G34: موفق
A35: 34 | B35: Multi-Filter | C35: دو فیلتر از دو جدول متفاوت | D35: چند نفر از کارکنان با تعلق شغلی عالی، حقوق بالای ۱۲۰۰۰ دارند؟ | E35: فیلتر از employee_performance و employee_salary هم‌زمان درست کار کند | F35: در بین کارکنان با تعلق شغلی "عالی" و بازه حقوق "12000+"، تعداد کل کارکنان ۱۹ نفر است. | G35: موفق | H35: کارت میانگین حقوق را در این صفحه رضایت داریم و نه فیلتر حقوق، بنابر این با دکس تایید شد
A36: 35 | B36: Multi-Filter | C36: سه فیلتر ترکیبی | D36: وضعیت ریسک کارکنان مجرد با سابقه‌کاری کمتر از ۲ سال را تحلیل کن | E36: سه فیلتر با هم روی صفحه‌ی ریسک | F36: تعداد پرسنل پرریسک در بین کارکنان مجرد با سابقه‌کاری ۰ تا ۲ سال، ۳۱ است. | G36: موفق
A37: 36 | B37: Multi-Filter | C37: فیلتر بازه‌ای دوگانه | D37: نرخ ترک خدمت کارکنان بالای ۵۵ سال با حقوق زیر ۴۰۰۰ دلار چقدر است؟ | E37: گروه سنی و بازه حقوق هم‌زمان | F37: در بین کارکنانی که سن آن‌ها بیشتر از ۵۵ سال و بازه حقوق آن‌ها بین ۰ تا ۴۰۰۰ دلار است، نرخ ترک خدمت ۳۶.۳۶٪ است. | G37: موفق | H37: بازه حقوق رو به صورت فیلتر در صفحه ترک خدمت نداریم ولی با دکس تایید شد
A38: 37 | B38: Point | C38: فیلتر آموزش در سال گذشته | D38: تعداد کارکنانی که سال گذشته آموزش دیده‌اند چند نفرند؟ | E38: فیلتر «آموزش در سال گذشته» درست اعمال شود | F38: در مجموع، تعداد کل کارکنان با آموزش در سال گذشته بیشتر از صفر، ۱۴۱۶ نفر است. | G38: موفق | H38: با دکس تایید شد
A39: 38 | B39: Point | C39: فیلتر آموزش با مقدار صفر | D39: کارکنانی که سال گذشته هیچ آموزشی ندیده‌اند چند نفرند؟ | E39: مقدار صفر/عدمِ آموزش درست تفسیر شود | F39: در بین کارکنان، تعداد کل کارکنان برابر با ۵۴ نفر است. | G39: موفق | H39: با دکس تایید شد
A40: 39 | B40: Point | C40: فیلتر مستقیم سطح ریسک | D40: چند نفر از کارکنان واحد فروش سطح ریسک بالا دارند؟ | E40: فیلتر سطح ریسک=بالا + واحد سازمانی با هم اعمال شود | F40: در بین واحد سازمانی "تحقیق و توسعه"، تعداد پرسنل پرریسک برابر با ۸۱ نفر است. | G40: موفق
...

Sheet خلاصه
A1: خلاصه‌ی نتایج تست
A3: دسته‌بندی | B3: تعداد کل | C3: موفق | D3: ناموفق | E3: درصد موفقیت
A4: Point | B4: =COUNTIF(تست‌ها!$B$2:$B$101,A4) -> 29 | C4: =COUNTIFS(تست‌ها!$B$2:$B$101,A4,تست‌ها!$G$2:$G$101,"موفق") -> 29 | D4: =COUNTIFS(تست‌ها!$B$2:$B$101,A4,تست‌ها!$G$2:$G$101,"ناموفق") -> 0 | E4: =IFERROR(C4/B4,0) -> 1
A5: Ranking | B5: =COUNTIF(تست‌ها!$B$2:$B$101,A5) -> 17 | C5: =COUNTIFS(تست‌ها!$B$2:$B$101,A5,تست‌ها!$G$2:$G$101,"موفق") -> 16 | D5: =COUNTIFS(تست‌ها!$B$2:$B$101,A5,تست‌ها!$G$2:$G$101,"ناموفق") -> 1 | E5: =IFERROR(C5/B5,0) -> 0.94117647
A6: Policy | B6: =COUNTIF(تست‌ها!$B$2:$B$101,A6) -> 9 | C6: =COUNTIFS(تست‌ها!$B$2:$B$101,A6,تست‌ها!$G$2:$G$101,"موفق") -> 9 | D6: =COUNTIFS(تست‌ها!$B$2:$B$101,A6,تست‌ها!$G$2:$G$101,"ناموفق") -> 0 | E6: =IFERROR(C6/B6,0) -> 1
A7: Image | B7: =COUNTIF(تست‌ها!$B$2:$B$101,A7) -> 10 | C7: =COUNTIFS(تست‌ها!$B$2:$B$101,A7,تست‌ها!$G$2:$G$101,"موفق") -> 10 | D7: =COUNTIFS(تست‌ها!$B$2:$B$101,A7,تست‌ها!$G$2:$G$101,"ناموفق") -> 0 | E7: =IFERROR(C7/B7,0) -> 1
A8: Edge Case | B8: =COUNTIF(تست‌ها!$B$2:$B$101,A8) -> 13 | C8: =COUNTIFS(تست‌ها!$B$2:$B$101,A8,تست‌ها!$G$2:$G$101,"موفق") -> 13 | D8: =COUNTIFS(تست‌ها!$B$2:$B$101,A8,تست‌ها!$G$2:$G$101,"ناموفق") -> 0 | E8: =IFERROR(C8/B8,0) -> 1
A9: Intent Classification | B9: =COUNTIF(تست‌ها!$B$2:$B$101,A9) -> 10 | C9: =COUNTIFS(تست‌ها!$B$2:$B$101,A9,تست‌ها!$G$2:$G$101,"موفق") -> 9 | D9: =COUNTIFS(تست‌ها!$B$2:$B$101,A9,تست‌ها!$G$2:$G$101,"ناموفق") -> 1 | E9: =IFERROR(C9/B9,0) -> 0.9
A10: Multi-Filter | B10: =COUNTIF(تست‌ها!$B$2:$B$101,A10) -> 12 | C10: =COUNTIFS(تست‌ها!$B$2:$B$101,A10,تست‌ها!$G$2:$G$101,"موفق") -> 12 | D10: =COUNTIFS(تست‌ها!$B$2:$B$101,A10,تست‌ها!$G$2:$G$101,"ناموفق") -> 0 | E10: =IFERROR(C10/B10,0) -> 1
A11: جمع کل | B11: =SUM(B4:B10) -> 100 | C11: =SUM(C4:C10) -> 98 | D11: =SUM(D4:D10) -> 2 | E11: =IFERROR(C11/B11,0) -> 0.98
A13: گزارش نهایی:
A14: ="اتوماسیون از بین "&B11&" سوال متنوع، "&C11&" مورد ("&TEXT(E11,"0.0%")&") را بدون خطا و با رفتار درست پاسخ داد." -> اتوماسیون از بین 100 سوال متنوع، 98 مورد (98.0%) را بدون خطا و با رفتار درست پاسخ داد.
